[2023-06-14T13:45:11.191+0000] {taskinstance.py:1103} INFO - Dependencies all met for dep_context=non-requeueable deps ti=<TaskInstance: postgres_dag.insert_values scheduled__2023-04-25T00:00:00+00:00 [queued]>
[2023-06-14T13:45:11.236+0000] {taskinstance.py:1103} INFO - Dependencies all met for dep_context=requeueable deps ti=<TaskInstance: postgres_dag.insert_values scheduled__2023-04-25T00:00:00+00:00 [queued]>
[2023-06-14T13:45:11.237+0000] {taskinstance.py:1308} INFO - Starting attempt 1 of 2
[2023-06-14T13:45:11.331+0000] {taskinstance.py:1327} INFO - Executing <Task(PostgresOperator): insert_values> on 2023-04-25 00:00:00+00:00
[2023-06-14T13:45:11.355+0000] {standard_task_runner.py:57} INFO - Started process 300 to run task
[2023-06-14T13:45:11.389+0000] {standard_task_runner.py:84} INFO - Running: ['***', 'tasks', 'run', 'postgres_dag', 'insert_values', 'scheduled__2023-04-25T00:00:00+00:00', '--job-id', '49', '--raw', '--subdir', 'DAGS_FOLDER/create_database_postgres.py', '--cfg-path', '/tmp/tmpatv1cj38']
[2023-06-14T13:45:11.390+0000] {standard_task_runner.py:85} INFO - Job 49: Subtask insert_values
[2023-06-14T13:45:11.736+0000] {task_command.py:410} INFO - Running <TaskInstance: postgres_dag.insert_values scheduled__2023-04-25T00:00:00+00:00 [running]> on host 770b1916921e
[2023-06-14T13:45:11.979+0000] {taskinstance.py:1547} INFO - Exporting env vars: AIRFLOW_CTX_DAG_OWNER='***' AIRFLOW_CTX_DAG_ID='postgres_dag' AIRFLOW_CTX_TASK_ID='insert_values' AIRFLOW_CTX_EXECUTION_DATE='2023-04-25T00:00:00+00:00' AIRFLOW_CTX_TRY_NUMBER='1' AIRFLOW_CTX_DAG_RUN_ID='scheduled__2023-04-25T00:00:00+00:00'
[2023-06-14T13:45:11.981+0000] {sql.py:262} INFO - Executing: 
INSERT INTO myTime VALUES (CURRENT_TIMESTAMP);
[2023-06-14T13:45:12.023+0000] {taskinstance.py:1824} ERROR - Task failed with exception
Traceback (most recent call last):
  File "/home/airflow/.local/lib/python3.7/site-packages/airflow/providers/common/sql/operators/sql.py", line 263, in execute
    hook = self.get_db_hook()
  File "/home/airflow/.local/lib/python3.7/site-packages/airflow/providers/common/sql/operators/sql.py", line 181, in get_db_hook
    return self._hook
  File "/home/airflow/.local/lib/python3.7/site-packages/cached_property.py", line 36, in __get__
    value = obj.__dict__[self.func.__name__] = self.func(obj)
  File "/home/airflow/.local/lib/python3.7/site-packages/airflow/providers/common/sql/operators/sql.py", line 143, in _hook
    conn = BaseHook.get_connection(self.conn_id)
  File "/home/airflow/.local/lib/python3.7/site-packages/airflow/hooks/base.py", line 72, in get_connection
    conn = Connection.get_connection_from_secrets(conn_id)
  File "/home/airflow/.local/lib/python3.7/site-packages/airflow/models/connection.py", line 434, in get_connection_from_secrets
    raise AirflowNotFoundException(f"The conn_id `{conn_id}` isn't defined")
airflow.exceptions.AirflowNotFoundException: The conn_id `postgres_conn` isn't defined
[2023-06-14T13:45:12.027+0000] {taskinstance.py:1350} INFO - Marking task as UP_FOR_RETRY. dag_id=postgres_dag, task_id=insert_values, execution_date=20230425T000000, start_date=20230614T134511, end_date=20230614T134512
[2023-06-14T13:45:12.047+0000] {standard_task_runner.py:109} ERROR - Failed to execute job 49 for task insert_values (The conn_id `postgres_conn` isn't defined; 300)
[2023-06-14T13:45:12.089+0000] {local_task_job_runner.py:225} INFO - Task exited with return code 1
[2023-06-14T13:45:12.107+0000] {taskinstance.py:2651} INFO - 0 downstream tasks scheduled from follow-on schedule check
[2023-06-14T13:54:06.934+0000] {taskinstance.py:1103} INFO - Dependencies all met for dep_context=non-requeueable deps ti=<TaskInstance: postgres_dag.insert_values scheduled__2023-04-25T00:00:00+00:00 [queued]>
[2023-06-14T13:54:06.975+0000] {taskinstance.py:1103} INFO - Dependencies all met for dep_context=requeueable deps ti=<TaskInstance: postgres_dag.insert_values scheduled__2023-04-25T00:00:00+00:00 [queued]>
[2023-06-14T13:54:06.980+0000] {taskinstance.py:1308} INFO - Starting attempt 1 of 2
[2023-06-14T13:54:07.017+0000] {taskinstance.py:1327} INFO - Executing <Task(PostgresOperator): insert_values> on 2023-04-25 00:00:00+00:00
[2023-06-14T13:54:07.037+0000] {standard_task_runner.py:57} INFO - Started process 117 to run task
[2023-06-14T13:54:07.052+0000] {standard_task_runner.py:84} INFO - Running: ['***', 'tasks', 'run', 'postgres_dag', 'insert_values', 'scheduled__2023-04-25T00:00:00+00:00', '--job-id', '23', '--raw', '--subdir', 'DAGS_FOLDER/create_database_postgres.py', '--cfg-path', '/tmp/tmpsv8xc7uw']
[2023-06-14T13:54:07.057+0000] {standard_task_runner.py:85} INFO - Job 23: Subtask insert_values
[2023-06-14T13:54:07.145+0000] {task_command.py:410} INFO - Running <TaskInstance: postgres_dag.insert_values scheduled__2023-04-25T00:00:00+00:00 [running]> on host e981f43aaef1
[2023-06-14T13:54:07.319+0000] {taskinstance.py:1547} INFO - Exporting env vars: AIRFLOW_CTX_DAG_OWNER='***' AIRFLOW_CTX_DAG_ID='postgres_dag' AIRFLOW_CTX_TASK_ID='insert_values' AIRFLOW_CTX_EXECUTION_DATE='2023-04-25T00:00:00+00:00' AIRFLOW_CTX_TRY_NUMBER='1' AIRFLOW_CTX_DAG_RUN_ID='scheduled__2023-04-25T00:00:00+00:00'
[2023-06-14T13:54:07.325+0000] {sql.py:262} INFO - Executing: 
INSERT INTO myTime VALUES (CURRENT_TIMESTAMP);
[2023-06-14T13:54:07.400+0000] {taskinstance.py:1824} ERROR - Task failed with exception
Traceback (most recent call last):
  File "/home/airflow/.local/lib/python3.7/site-packages/airflow/providers/common/sql/operators/sql.py", line 263, in execute
    hook = self.get_db_hook()
  File "/home/airflow/.local/lib/python3.7/site-packages/airflow/providers/common/sql/operators/sql.py", line 181, in get_db_hook
    return self._hook
  File "/home/airflow/.local/lib/python3.7/site-packages/cached_property.py", line 36, in __get__
    value = obj.__dict__[self.func.__name__] = self.func(obj)
  File "/home/airflow/.local/lib/python3.7/site-packages/airflow/providers/common/sql/operators/sql.py", line 143, in _hook
    conn = BaseHook.get_connection(self.conn_id)
  File "/home/airflow/.local/lib/python3.7/site-packages/airflow/hooks/base.py", line 72, in get_connection
    conn = Connection.get_connection_from_secrets(conn_id)
  File "/home/airflow/.local/lib/python3.7/site-packages/airflow/models/connection.py", line 434, in get_connection_from_secrets
    raise AirflowNotFoundException(f"The conn_id `{conn_id}` isn't defined")
airflow.exceptions.AirflowNotFoundException: The conn_id `postgres_conn` isn't defined
[2023-06-14T13:54:07.412+0000] {taskinstance.py:1350} INFO - Marking task as UP_FOR_RETRY. dag_id=postgres_dag, task_id=insert_values, execution_date=20230425T000000, start_date=20230614T135406, end_date=20230614T135407
[2023-06-14T13:54:07.435+0000] {standard_task_runner.py:109} ERROR - Failed to execute job 23 for task insert_values (The conn_id `postgres_conn` isn't defined; 117)
[2023-06-14T13:54:07.509+0000] {local_task_job_runner.py:225} INFO - Task exited with return code 1
[2023-06-14T13:54:07.556+0000] {taskinstance.py:2651} INFO - 0 downstream tasks scheduled from follow-on schedule check
[2023-06-14T13:56:53.443+0000] {taskinstance.py:1103} INFO - Dependencies all met for dep_context=non-requeueable deps ti=<TaskInstance: postgres_dag.insert_values scheduled__2023-04-25T00:00:00+00:00 [queued]>
[2023-06-14T13:56:53.467+0000] {taskinstance.py:1103} INFO - Dependencies all met for dep_context=requeueable deps ti=<TaskInstance: postgres_dag.insert_values scheduled__2023-04-25T00:00:00+00:00 [queued]>
[2023-06-14T13:56:53.476+0000] {taskinstance.py:1308} INFO - Starting attempt 1 of 2
[2023-06-14T13:56:53.504+0000] {taskinstance.py:1327} INFO - Executing <Task(PostgresOperator): insert_values> on 2023-04-25 00:00:00+00:00
[2023-06-14T13:56:53.510+0000] {standard_task_runner.py:57} INFO - Started process 111 to run task
[2023-06-14T13:56:53.552+0000] {standard_task_runner.py:84} INFO - Running: ['***', 'tasks', 'run', 'postgres_dag', 'insert_values', 'scheduled__2023-04-25T00:00:00+00:00', '--job-id', '23', '--raw', '--subdir', 'DAGS_FOLDER/create_database_postgres.py', '--cfg-path', '/tmp/tmpm5_e6as3']
[2023-06-14T13:56:53.557+0000] {standard_task_runner.py:85} INFO - Job 23: Subtask insert_values
[2023-06-14T13:56:53.714+0000] {task_command.py:410} INFO - Running <TaskInstance: postgres_dag.insert_values scheduled__2023-04-25T00:00:00+00:00 [running]> on host 366197f8877d
[2023-06-14T13:56:53.844+0000] {taskinstance.py:1547} INFO - Exporting env vars: AIRFLOW_CTX_DAG_OWNER='***' AIRFLOW_CTX_DAG_ID='postgres_dag' AIRFLOW_CTX_TASK_ID='insert_values' AIRFLOW_CTX_EXECUTION_DATE='2023-04-25T00:00:00+00:00' AIRFLOW_CTX_TRY_NUMBER='1' AIRFLOW_CTX_DAG_RUN_ID='scheduled__2023-04-25T00:00:00+00:00'
[2023-06-14T13:56:53.846+0000] {sql.py:262} INFO - Executing: 
INSERT INTO myTime VALUES (CURRENT_TIMESTAMP);
[2023-06-14T13:56:53.864+0000] {base.py:73} INFO - Using connection ID 'postgres_connection' for task execution.
[2023-06-14T13:56:53.952+0000] {base.py:73} INFO - Using connection ID 'postgres_connection' for task execution.
[2023-06-14T13:56:53.970+0000] {sql.py:375} INFO - Running statement: 
INSERT INTO myTime VALUES (CURRENT_TIMESTAMP);, parameters: None
[2023-06-14T13:56:53.974+0000] {taskinstance.py:1824} ERROR - Task failed with exception
Traceback (most recent call last):
  File "/home/airflow/.local/lib/python3.7/site-packages/airflow/providers/common/sql/operators/sql.py", line 274, in execute
    **extra_kwargs,
  File "/home/airflow/.local/lib/python3.7/site-packages/airflow/providers/common/sql/hooks/sql.py", line 349, in run
    self._run_command(cur, sql_statement, parameters)
  File "/home/airflow/.local/lib/python3.7/site-packages/airflow/providers/common/sql/hooks/sql.py", line 380, in _run_command
    cur.execute(sql_statement)
psycopg2.errors.UndefinedTable: relation "mytime" does not exist
LINE 2: INSERT INTO myTime VALUES (CURRENT_TIMESTAMP);
                    ^

[2023-06-14T13:56:54.001+0000] {taskinstance.py:1350} INFO - Marking task as UP_FOR_RETRY. dag_id=postgres_dag, task_id=insert_values, execution_date=20230425T000000, start_date=20230614T135653, end_date=20230614T135654
[2023-06-14T13:56:54.036+0000] {standard_task_runner.py:109} ERROR - Failed to execute job 23 for task insert_values (relation "mytime" does not exist
LINE 2: INSERT INTO myTime VALUES (CURRENT_TIMESTAMP);
                    ^
; 111)
[2023-06-14T13:56:54.163+0000] {local_task_job_runner.py:225} INFO - Task exited with return code 1
[2023-06-14T13:56:54.187+0000] {taskinstance.py:2651} INFO - 0 downstream tasks scheduled from follow-on schedule check
