[2023-06-14T13:45:10.891+0000] {taskinstance.py:1103} INFO - Dependencies all met for dep_context=non-requeueable deps ti=<TaskInstance: postgres_dag.insert_values scheduled__2023-04-30T00:00:00+00:00 [queued]>
[2023-06-14T13:45:10.935+0000] {taskinstance.py:1103} INFO - Dependencies all met for dep_context=requeueable deps ti=<TaskInstance: postgres_dag.insert_values scheduled__2023-04-30T00:00:00+00:00 [queued]>
[2023-06-14T13:45:10.936+0000] {taskinstance.py:1308} INFO - Starting attempt 1 of 2
[2023-06-14T13:45:10.999+0000] {taskinstance.py:1327} INFO - Executing <Task(PostgresOperator): insert_values> on 2023-04-30 00:00:00+00:00
[2023-06-14T13:45:11.037+0000] {standard_task_runner.py:57} INFO - Started process 294 to run task
[2023-06-14T13:45:11.089+0000] {standard_task_runner.py:84} INFO - Running: ['***', 'tasks', 'run', 'postgres_dag', 'insert_values', 'scheduled__2023-04-30T00:00:00+00:00', '--job-id', '43', '--raw', '--subdir', 'DAGS_FOLDER/create_database_postgres.py', '--cfg-path', '/tmp/tmptznz5h9u']
[2023-06-14T13:45:11.110+0000] {standard_task_runner.py:85} INFO - Job 43: Subtask insert_values
[2023-06-14T13:45:11.285+0000] {task_command.py:410} INFO - Running <TaskInstance: postgres_dag.insert_values scheduled__2023-04-30T00:00:00+00:00 [running]> on host 770b1916921e
[2023-06-14T13:45:11.569+0000] {taskinstance.py:1547} INFO - Exporting env vars: AIRFLOW_CTX_DAG_OWNER='***' AIRFLOW_CTX_DAG_ID='postgres_dag' AIRFLOW_CTX_TASK_ID='insert_values' AIRFLOW_CTX_EXECUTION_DATE='2023-04-30T00:00:00+00:00' AIRFLOW_CTX_TRY_NUMBER='1' AIRFLOW_CTX_DAG_RUN_ID='scheduled__2023-04-30T00:00:00+00:00'
[2023-06-14T13:45:11.575+0000] {sql.py:262} INFO - Executing: 
INSERT INTO myTime VALUES (CURRENT_TIMESTAMP);
[2023-06-14T13:45:11.643+0000] {taskinstance.py:1824} ERROR - Task failed with exception
Traceback (most recent call last):
  File "/home/airflow/.local/lib/python3.7/site-packages/airflow/providers/common/sql/operators/sql.py", line 263, in execute
    hook = self.get_db_hook()
  File "/home/airflow/.local/lib/python3.7/site-packages/airflow/providers/common/sql/operators/sql.py", line 181, in get_db_hook
    return self._hook
  File "/home/airflow/.local/lib/python3.7/site-packages/cached_property.py", line 36, in __get__
    value = obj.__dict__[self.func.__name__] = self.func(obj)
  File "/home/airflow/.local/lib/python3.7/site-packages/airflow/providers/common/sql/operators/sql.py", line 143, in _hook
    conn = BaseHook.get_connection(self.conn_id)
  File "/home/airflow/.local/lib/python3.7/site-packages/airflow/hooks/base.py", line 72, in get_connection
    conn = Connection.get_connection_from_secrets(conn_id)
  File "/home/airflow/.local/lib/python3.7/site-packages/airflow/models/connection.py", line 434, in get_connection_from_secrets
    raise AirflowNotFoundException(f"The conn_id `{conn_id}` isn't defined")
airflow.exceptions.AirflowNotFoundException: The conn_id `postgres_conn` isn't defined
[2023-06-14T13:45:11.648+0000] {taskinstance.py:1350} INFO - Marking task as UP_FOR_RETRY. dag_id=postgres_dag, task_id=insert_values, execution_date=20230430T000000, start_date=20230614T134510, end_date=20230614T134511
[2023-06-14T13:45:11.696+0000] {standard_task_runner.py:109} ERROR - Failed to execute job 43 for task insert_values (The conn_id `postgres_conn` isn't defined; 294)
[2023-06-14T13:45:11.773+0000] {local_task_job_runner.py:225} INFO - Task exited with return code 1
[2023-06-14T13:45:11.827+0000] {taskinstance.py:2651} INFO - 0 downstream tasks scheduled from follow-on schedule check
[2023-06-14T13:54:07.696+0000] {taskinstance.py:1103} INFO - Dependencies all met for dep_context=non-requeueable deps ti=<TaskInstance: postgres_dag.insert_values scheduled__2023-04-30T00:00:00+00:00 [queued]>
[2023-06-14T13:54:07.730+0000] {taskinstance.py:1103} INFO - Dependencies all met for dep_context=requeueable deps ti=<TaskInstance: postgres_dag.insert_values scheduled__2023-04-30T00:00:00+00:00 [queued]>
[2023-06-14T13:54:07.736+0000] {taskinstance.py:1308} INFO - Starting attempt 1 of 2
[2023-06-14T13:54:07.789+0000] {taskinstance.py:1327} INFO - Executing <Task(PostgresOperator): insert_values> on 2023-04-30 00:00:00+00:00
[2023-06-14T13:54:07.804+0000] {standard_task_runner.py:57} INFO - Started process 125 to run task
[2023-06-14T13:54:07.831+0000] {standard_task_runner.py:84} INFO - Running: ['***', 'tasks', 'run', 'postgres_dag', 'insert_values', 'scheduled__2023-04-30T00:00:00+00:00', '--job-id', '26', '--raw', '--subdir', 'DAGS_FOLDER/create_database_postgres.py', '--cfg-path', '/tmp/tmp8vlwlp9m']
[2023-06-14T13:54:07.838+0000] {standard_task_runner.py:85} INFO - Job 26: Subtask insert_values
[2023-06-14T13:54:08.031+0000] {task_command.py:410} INFO - Running <TaskInstance: postgres_dag.insert_values scheduled__2023-04-30T00:00:00+00:00 [running]> on host e981f43aaef1
[2023-06-14T13:54:08.235+0000] {taskinstance.py:1547} INFO - Exporting env vars: AIRFLOW_CTX_DAG_OWNER='***' AIRFLOW_CTX_DAG_ID='postgres_dag' AIRFLOW_CTX_TASK_ID='insert_values' AIRFLOW_CTX_EXECUTION_DATE='2023-04-30T00:00:00+00:00' AIRFLOW_CTX_TRY_NUMBER='1' AIRFLOW_CTX_DAG_RUN_ID='scheduled__2023-04-30T00:00:00+00:00'
[2023-06-14T13:54:08.237+0000] {sql.py:262} INFO - Executing: 
INSERT INTO myTime VALUES (CURRENT_TIMESTAMP);
[2023-06-14T13:54:08.284+0000] {taskinstance.py:1824} ERROR - Task failed with exception
Traceback (most recent call last):
  File "/home/airflow/.local/lib/python3.7/site-packages/airflow/providers/common/sql/operators/sql.py", line 263, in execute
    hook = self.get_db_hook()
  File "/home/airflow/.local/lib/python3.7/site-packages/airflow/providers/common/sql/operators/sql.py", line 181, in get_db_hook
    return self._hook
  File "/home/airflow/.local/lib/python3.7/site-packages/cached_property.py", line 36, in __get__
    value = obj.__dict__[self.func.__name__] = self.func(obj)
  File "/home/airflow/.local/lib/python3.7/site-packages/airflow/providers/common/sql/operators/sql.py", line 143, in _hook
    conn = BaseHook.get_connection(self.conn_id)
  File "/home/airflow/.local/lib/python3.7/site-packages/airflow/hooks/base.py", line 72, in get_connection
    conn = Connection.get_connection_from_secrets(conn_id)
  File "/home/airflow/.local/lib/python3.7/site-packages/airflow/models/connection.py", line 434, in get_connection_from_secrets
    raise AirflowNotFoundException(f"The conn_id `{conn_id}` isn't defined")
airflow.exceptions.AirflowNotFoundException: The conn_id `postgres_conn` isn't defined
[2023-06-14T13:54:08.292+0000] {taskinstance.py:1350} INFO - Marking task as UP_FOR_RETRY. dag_id=postgres_dag, task_id=insert_values, execution_date=20230430T000000, start_date=20230614T135407, end_date=20230614T135408
[2023-06-14T13:54:08.311+0000] {standard_task_runner.py:109} ERROR - Failed to execute job 26 for task insert_values (The conn_id `postgres_conn` isn't defined; 125)
[2023-06-14T13:54:08.365+0000] {local_task_job_runner.py:225} INFO - Task exited with return code 1
[2023-06-14T13:54:08.395+0000] {taskinstance.py:2651} INFO - 0 downstream tasks scheduled from follow-on schedule check
[2023-06-14T13:56:54.878+0000] {taskinstance.py:1103} INFO - Dependencies all met for dep_context=non-requeueable deps ti=<TaskInstance: postgres_dag.insert_values scheduled__2023-04-30T00:00:00+00:00 [queued]>
[2023-06-14T13:56:54.915+0000] {taskinstance.py:1103} INFO - Dependencies all met for dep_context=requeueable deps ti=<TaskInstance: postgres_dag.insert_values scheduled__2023-04-30T00:00:00+00:00 [queued]>
[2023-06-14T13:56:54.921+0000] {taskinstance.py:1308} INFO - Starting attempt 1 of 2
[2023-06-14T13:56:54.950+0000] {taskinstance.py:1327} INFO - Executing <Task(PostgresOperator): insert_values> on 2023-04-30 00:00:00+00:00
[2023-06-14T13:56:54.966+0000] {standard_task_runner.py:57} INFO - Started process 129 to run task
[2023-06-14T13:56:54.979+0000] {standard_task_runner.py:84} INFO - Running: ['***', 'tasks', 'run', 'postgres_dag', 'insert_values', 'scheduled__2023-04-30T00:00:00+00:00', '--job-id', '33', '--raw', '--subdir', 'DAGS_FOLDER/create_database_postgres.py', '--cfg-path', '/tmp/tmpuwswc0ir']
[2023-06-14T13:56:54.982+0000] {standard_task_runner.py:85} INFO - Job 33: Subtask insert_values
[2023-06-14T13:56:55.161+0000] {task_command.py:410} INFO - Running <TaskInstance: postgres_dag.insert_values scheduled__2023-04-30T00:00:00+00:00 [running]> on host 366197f8877d
[2023-06-14T13:56:55.325+0000] {taskinstance.py:1547} INFO - Exporting env vars: AIRFLOW_CTX_DAG_OWNER='***' AIRFLOW_CTX_DAG_ID='postgres_dag' AIRFLOW_CTX_TASK_ID='insert_values' AIRFLOW_CTX_EXECUTION_DATE='2023-04-30T00:00:00+00:00' AIRFLOW_CTX_TRY_NUMBER='1' AIRFLOW_CTX_DAG_RUN_ID='scheduled__2023-04-30T00:00:00+00:00'
[2023-06-14T13:56:55.329+0000] {sql.py:262} INFO - Executing: 
INSERT INTO myTime VALUES (CURRENT_TIMESTAMP);
[2023-06-14T13:56:55.341+0000] {base.py:73} INFO - Using connection ID 'postgres_connection' for task execution.
[2023-06-14T13:56:55.437+0000] {base.py:73} INFO - Using connection ID 'postgres_connection' for task execution.
[2023-06-14T13:56:55.466+0000] {sql.py:375} INFO - Running statement: 
INSERT INTO myTime VALUES (CURRENT_TIMESTAMP);, parameters: None
[2023-06-14T13:56:55.471+0000] {taskinstance.py:1824} ERROR - Task failed with exception
Traceback (most recent call last):
  File "/home/airflow/.local/lib/python3.7/site-packages/airflow/providers/common/sql/operators/sql.py", line 274, in execute
    **extra_kwargs,
  File "/home/airflow/.local/lib/python3.7/site-packages/airflow/providers/common/sql/hooks/sql.py", line 349, in run
    self._run_command(cur, sql_statement, parameters)
  File "/home/airflow/.local/lib/python3.7/site-packages/airflow/providers/common/sql/hooks/sql.py", line 380, in _run_command
    cur.execute(sql_statement)
psycopg2.errors.UndefinedTable: relation "mytime" does not exist
LINE 2: INSERT INTO myTime VALUES (CURRENT_TIMESTAMP);
                    ^

[2023-06-14T13:56:55.487+0000] {taskinstance.py:1350} INFO - Marking task as UP_FOR_RETRY. dag_id=postgres_dag, task_id=insert_values, execution_date=20230430T000000, start_date=20230614T135654, end_date=20230614T135655
[2023-06-14T13:56:55.502+0000] {standard_task_runner.py:109} ERROR - Failed to execute job 33 for task insert_values (relation "mytime" does not exist
LINE 2: INSERT INTO myTime VALUES (CURRENT_TIMESTAMP);
                    ^
; 129)
[2023-06-14T13:56:55.528+0000] {local_task_job_runner.py:225} INFO - Task exited with return code 1
[2023-06-14T13:56:55.622+0000] {taskinstance.py:2651} INFO - 0 downstream tasks scheduled from follow-on schedule check
