[2023-06-14T13:45:10.707+0000] {taskinstance.py:1103} INFO - Dependencies all met for dep_context=non-requeueable deps ti=<TaskInstance: postgres_dag.insert_values scheduled__2023-05-03T00:00:00+00:00 [queued]>
[2023-06-14T13:45:10.741+0000] {taskinstance.py:1103} INFO - Dependencies all met for dep_context=requeueable deps ti=<TaskInstance: postgres_dag.insert_values scheduled__2023-05-03T00:00:00+00:00 [queued]>
[2023-06-14T13:45:10.753+0000] {taskinstance.py:1308} INFO - Starting attempt 1 of 2
[2023-06-14T13:45:10.845+0000] {taskinstance.py:1327} INFO - Executing <Task(PostgresOperator): insert_values> on 2023-05-03 00:00:00+00:00
[2023-06-14T13:45:10.866+0000] {standard_task_runner.py:57} INFO - Started process 292 to run task
[2023-06-14T13:45:10.894+0000] {standard_task_runner.py:84} INFO - Running: ['***', 'tasks', 'run', 'postgres_dag', 'insert_values', 'scheduled__2023-05-03T00:00:00+00:00', '--job-id', '42', '--raw', '--subdir', 'DAGS_FOLDER/create_database_postgres.py', '--cfg-path', '/tmp/tmpjdqz56jh']
[2023-06-14T13:45:10.899+0000] {standard_task_runner.py:85} INFO - Job 42: Subtask insert_values
[2023-06-14T13:45:11.186+0000] {task_command.py:410} INFO - Running <TaskInstance: postgres_dag.insert_values scheduled__2023-05-03T00:00:00+00:00 [running]> on host 770b1916921e
[2023-06-14T13:45:11.540+0000] {taskinstance.py:1547} INFO - Exporting env vars: AIRFLOW_CTX_DAG_OWNER='***' AIRFLOW_CTX_DAG_ID='postgres_dag' AIRFLOW_CTX_TASK_ID='insert_values' AIRFLOW_CTX_EXECUTION_DATE='2023-05-03T00:00:00+00:00' AIRFLOW_CTX_TRY_NUMBER='1' AIRFLOW_CTX_DAG_RUN_ID='scheduled__2023-05-03T00:00:00+00:00'
[2023-06-14T13:45:11.543+0000] {sql.py:262} INFO - Executing: 
INSERT INTO myTime VALUES (CURRENT_TIMESTAMP);
[2023-06-14T13:45:11.643+0000] {taskinstance.py:1824} ERROR - Task failed with exception
Traceback (most recent call last):
  File "/home/airflow/.local/lib/python3.7/site-packages/airflow/providers/common/sql/operators/sql.py", line 263, in execute
    hook = self.get_db_hook()
  File "/home/airflow/.local/lib/python3.7/site-packages/airflow/providers/common/sql/operators/sql.py", line 181, in get_db_hook
    return self._hook
  File "/home/airflow/.local/lib/python3.7/site-packages/cached_property.py", line 36, in __get__
    value = obj.__dict__[self.func.__name__] = self.func(obj)
  File "/home/airflow/.local/lib/python3.7/site-packages/airflow/providers/common/sql/operators/sql.py", line 143, in _hook
    conn = BaseHook.get_connection(self.conn_id)
  File "/home/airflow/.local/lib/python3.7/site-packages/airflow/hooks/base.py", line 72, in get_connection
    conn = Connection.get_connection_from_secrets(conn_id)
  File "/home/airflow/.local/lib/python3.7/site-packages/airflow/models/connection.py", line 434, in get_connection_from_secrets
    raise AirflowNotFoundException(f"The conn_id `{conn_id}` isn't defined")
airflow.exceptions.AirflowNotFoundException: The conn_id `postgres_conn` isn't defined
[2023-06-14T13:45:11.660+0000] {taskinstance.py:1350} INFO - Marking task as UP_FOR_RETRY. dag_id=postgres_dag, task_id=insert_values, execution_date=20230503T000000, start_date=20230614T134510, end_date=20230614T134511
[2023-06-14T13:45:11.739+0000] {standard_task_runner.py:109} ERROR - Failed to execute job 42 for task insert_values (The conn_id `postgres_conn` isn't defined; 292)
[2023-06-14T13:45:11.851+0000] {local_task_job_runner.py:225} INFO - Task exited with return code 1
[2023-06-14T13:45:11.884+0000] {taskinstance.py:2651} INFO - 0 downstream tasks scheduled from follow-on schedule check
[2023-06-14T13:54:08.741+0000] {taskinstance.py:1103} INFO - Dependencies all met for dep_context=non-requeueable deps ti=<TaskInstance: postgres_dag.insert_values scheduled__2023-05-03T00:00:00+00:00 [queued]>
[2023-06-14T13:54:08.749+0000] {taskinstance.py:1103} INFO - Dependencies all met for dep_context=requeueable deps ti=<TaskInstance: postgres_dag.insert_values scheduled__2023-05-03T00:00:00+00:00 [queued]>
[2023-06-14T13:54:08.749+0000] {taskinstance.py:1308} INFO - Starting attempt 1 of 2
[2023-06-14T13:54:08.763+0000] {taskinstance.py:1327} INFO - Executing <Task(PostgresOperator): insert_values> on 2023-05-03 00:00:00+00:00
[2023-06-14T13:54:08.769+0000] {standard_task_runner.py:57} INFO - Started process 133 to run task
[2023-06-14T13:54:08.776+0000] {standard_task_runner.py:84} INFO - Running: ['***', 'tasks', 'run', 'postgres_dag', 'insert_values', 'scheduled__2023-05-03T00:00:00+00:00', '--job-id', '34', '--raw', '--subdir', 'DAGS_FOLDER/create_database_postgres.py', '--cfg-path', '/tmp/tmpwjzsbdk1']
[2023-06-14T13:54:08.778+0000] {standard_task_runner.py:85} INFO - Job 34: Subtask insert_values
[2023-06-14T13:54:08.845+0000] {task_command.py:410} INFO - Running <TaskInstance: postgres_dag.insert_values scheduled__2023-05-03T00:00:00+00:00 [running]> on host e981f43aaef1
[2023-06-14T13:54:08.932+0000] {taskinstance.py:1547} INFO - Exporting env vars: AIRFLOW_CTX_DAG_OWNER='***' AIRFLOW_CTX_DAG_ID='postgres_dag' AIRFLOW_CTX_TASK_ID='insert_values' AIRFLOW_CTX_EXECUTION_DATE='2023-05-03T00:00:00+00:00' AIRFLOW_CTX_TRY_NUMBER='1' AIRFLOW_CTX_DAG_RUN_ID='scheduled__2023-05-03T00:00:00+00:00'
[2023-06-14T13:54:08.933+0000] {sql.py:262} INFO - Executing: 
INSERT INTO myTime VALUES (CURRENT_TIMESTAMP);
[2023-06-14T13:54:08.957+0000] {taskinstance.py:1824} ERROR - Task failed with exception
Traceback (most recent call last):
  File "/home/airflow/.local/lib/python3.7/site-packages/airflow/providers/common/sql/operators/sql.py", line 263, in execute
    hook = self.get_db_hook()
  File "/home/airflow/.local/lib/python3.7/site-packages/airflow/providers/common/sql/operators/sql.py", line 181, in get_db_hook
    return self._hook
  File "/home/airflow/.local/lib/python3.7/site-packages/cached_property.py", line 36, in __get__
    value = obj.__dict__[self.func.__name__] = self.func(obj)
  File "/home/airflow/.local/lib/python3.7/site-packages/airflow/providers/common/sql/operators/sql.py", line 143, in _hook
    conn = BaseHook.get_connection(self.conn_id)
  File "/home/airflow/.local/lib/python3.7/site-packages/airflow/hooks/base.py", line 72, in get_connection
    conn = Connection.get_connection_from_secrets(conn_id)
  File "/home/airflow/.local/lib/python3.7/site-packages/airflow/models/connection.py", line 434, in get_connection_from_secrets
    raise AirflowNotFoundException(f"The conn_id `{conn_id}` isn't defined")
airflow.exceptions.AirflowNotFoundException: The conn_id `postgres_conn` isn't defined
[2023-06-14T13:54:08.961+0000] {taskinstance.py:1350} INFO - Marking task as UP_FOR_RETRY. dag_id=postgres_dag, task_id=insert_values, execution_date=20230503T000000, start_date=20230614T135408, end_date=20230614T135408
[2023-06-14T13:54:08.971+0000] {standard_task_runner.py:109} ERROR - Failed to execute job 34 for task insert_values (The conn_id `postgres_conn` isn't defined; 133)
[2023-06-14T13:54:08.995+0000] {local_task_job_runner.py:225} INFO - Task exited with return code 1
[2023-06-14T13:54:09.011+0000] {taskinstance.py:2651} INFO - 0 downstream tasks scheduled from follow-on schedule check
[2023-06-14T13:56:54.840+0000] {taskinstance.py:1103} INFO - Dependencies all met for dep_context=non-requeueable deps ti=<TaskInstance: postgres_dag.insert_values scheduled__2023-05-03T00:00:00+00:00 [queued]>
[2023-06-14T13:56:54.848+0000] {taskinstance.py:1103} INFO - Dependencies all met for dep_context=requeueable deps ti=<TaskInstance: postgres_dag.insert_values scheduled__2023-05-03T00:00:00+00:00 [queued]>
[2023-06-14T13:56:54.849+0000] {taskinstance.py:1308} INFO - Starting attempt 1 of 2
[2023-06-14T13:56:54.862+0000] {taskinstance.py:1327} INFO - Executing <Task(PostgresOperator): insert_values> on 2023-05-03 00:00:00+00:00
[2023-06-14T13:56:54.874+0000] {standard_task_runner.py:57} INFO - Started process 126 to run task
[2023-06-14T13:56:54.884+0000] {standard_task_runner.py:84} INFO - Running: ['***', 'tasks', 'run', 'postgres_dag', 'insert_values', 'scheduled__2023-05-03T00:00:00+00:00', '--job-id', '32', '--raw', '--subdir', 'DAGS_FOLDER/create_database_postgres.py', '--cfg-path', '/tmp/tmpyjbpam5m']
[2023-06-14T13:56:54.886+0000] {standard_task_runner.py:85} INFO - Job 32: Subtask insert_values
[2023-06-14T13:56:54.969+0000] {task_command.py:410} INFO - Running <TaskInstance: postgres_dag.insert_values scheduled__2023-05-03T00:00:00+00:00 [running]> on host 366197f8877d
[2023-06-14T13:56:55.179+0000] {taskinstance.py:1547} INFO - Exporting env vars: AIRFLOW_CTX_DAG_OWNER='***' AIRFLOW_CTX_DAG_ID='postgres_dag' AIRFLOW_CTX_TASK_ID='insert_values' AIRFLOW_CTX_EXECUTION_DATE='2023-05-03T00:00:00+00:00' AIRFLOW_CTX_TRY_NUMBER='1' AIRFLOW_CTX_DAG_RUN_ID='scheduled__2023-05-03T00:00:00+00:00'
[2023-06-14T13:56:55.183+0000] {sql.py:262} INFO - Executing: 
INSERT INTO myTime VALUES (CURRENT_TIMESTAMP);
[2023-06-14T13:56:55.205+0000] {base.py:73} INFO - Using connection ID 'postgres_connection' for task execution.
[2023-06-14T13:56:55.314+0000] {base.py:73} INFO - Using connection ID 'postgres_connection' for task execution.
[2023-06-14T13:56:55.323+0000] {sql.py:375} INFO - Running statement: 
INSERT INTO myTime VALUES (CURRENT_TIMESTAMP);, parameters: None
[2023-06-14T13:56:55.325+0000] {taskinstance.py:1824} ERROR - Task failed with exception
Traceback (most recent call last):
  File "/home/airflow/.local/lib/python3.7/site-packages/airflow/providers/common/sql/operators/sql.py", line 274, in execute
    **extra_kwargs,
  File "/home/airflow/.local/lib/python3.7/site-packages/airflow/providers/common/sql/hooks/sql.py", line 349, in run
    self._run_command(cur, sql_statement, parameters)
  File "/home/airflow/.local/lib/python3.7/site-packages/airflow/providers/common/sql/hooks/sql.py", line 380, in _run_command
    cur.execute(sql_statement)
psycopg2.errors.UndefinedTable: relation "mytime" does not exist
LINE 2: INSERT INTO myTime VALUES (CURRENT_TIMESTAMP);
                    ^

[2023-06-14T13:56:55.344+0000] {taskinstance.py:1350} INFO - Marking task as UP_FOR_RETRY. dag_id=postgres_dag, task_id=insert_values, execution_date=20230503T000000, start_date=20230614T135654, end_date=20230614T135655
[2023-06-14T13:56:55.354+0000] {standard_task_runner.py:109} ERROR - Failed to execute job 32 for task insert_values (relation "mytime" does not exist
LINE 2: INSERT INTO myTime VALUES (CURRENT_TIMESTAMP);
                    ^
; 126)
[2023-06-14T13:56:55.418+0000] {local_task_job_runner.py:225} INFO - Task exited with return code 1
[2023-06-14T13:56:55.452+0000] {taskinstance.py:2651} INFO - 0 downstream tasks scheduled from follow-on schedule check
