[2023-06-14T13:56:52.753+0000] {taskinstance.py:1103} INFO - Dependencies all met for dep_context=non-requeueable deps ti=<TaskInstance: postgres_dag.insert_values manual__2023-06-14T13:56:46.181185+00:00 [queued]>
[2023-06-14T13:56:52.773+0000] {taskinstance.py:1103} INFO - Dependencies all met for dep_context=requeueable deps ti=<TaskInstance: postgres_dag.insert_values manual__2023-06-14T13:56:46.181185+00:00 [queued]>
[2023-06-14T13:56:52.774+0000] {taskinstance.py:1308} INFO - Starting attempt 1 of 2
[2023-06-14T13:56:52.862+0000] {taskinstance.py:1327} INFO - Executing <Task(PostgresOperator): insert_values> on 2023-06-14 13:56:46.181185+00:00
[2023-06-14T13:56:52.869+0000] {standard_task_runner.py:57} INFO - Started process 108 to run task
[2023-06-14T13:56:52.876+0000] {standard_task_runner.py:84} INFO - Running: ['***', 'tasks', 'run', 'postgres_dag', 'insert_values', 'manual__2023-06-14T13:56:46.181185+00:00', '--job-id', '20', '--raw', '--subdir', 'DAGS_FOLDER/create_database_postgres.py', '--cfg-path', '/tmp/tmpfwa4lv0l']
[2023-06-14T13:56:52.878+0000] {standard_task_runner.py:85} INFO - Job 20: Subtask insert_values
[2023-06-14T13:56:53.079+0000] {task_command.py:410} INFO - Running <TaskInstance: postgres_dag.insert_values manual__2023-06-14T13:56:46.181185+00:00 [running]> on host 366197f8877d
[2023-06-14T13:56:53.400+0000] {taskinstance.py:1547} INFO - Exporting env vars: AIRFLOW_CTX_DAG_OWNER='***' AIRFLOW_CTX_DAG_ID='postgres_dag' AIRFLOW_CTX_TASK_ID='insert_values' AIRFLOW_CTX_EXECUTION_DATE='2023-06-14T13:56:46.181185+00:00' AIRFLOW_CTX_TRY_NUMBER='1' AIRFLOW_CTX_DAG_RUN_ID='manual__2023-06-14T13:56:46.181185+00:00'
[2023-06-14T13:56:53.401+0000] {sql.py:262} INFO - Executing: 
INSERT INTO myTime VALUES (CURRENT_TIMESTAMP);
[2023-06-14T13:56:53.420+0000] {base.py:73} INFO - Using connection ID 'postgres_connection' for task execution.
[2023-06-14T13:56:53.632+0000] {base.py:73} INFO - Using connection ID 'postgres_connection' for task execution.
[2023-06-14T13:56:53.655+0000] {sql.py:375} INFO - Running statement: 
INSERT INTO myTime VALUES (CURRENT_TIMESTAMP);, parameters: None
[2023-06-14T13:56:53.663+0000] {taskinstance.py:1824} ERROR - Task failed with exception
Traceback (most recent call last):
  File "/home/airflow/.local/lib/python3.7/site-packages/airflow/providers/common/sql/operators/sql.py", line 274, in execute
    **extra_kwargs,
  File "/home/airflow/.local/lib/python3.7/site-packages/airflow/providers/common/sql/hooks/sql.py", line 349, in run
    self._run_command(cur, sql_statement, parameters)
  File "/home/airflow/.local/lib/python3.7/site-packages/airflow/providers/common/sql/hooks/sql.py", line 380, in _run_command
    cur.execute(sql_statement)
psycopg2.errors.UndefinedTable: relation "mytime" does not exist
LINE 2: INSERT INTO myTime VALUES (CURRENT_TIMESTAMP);
                    ^

[2023-06-14T13:56:53.683+0000] {taskinstance.py:1350} INFO - Marking task as UP_FOR_RETRY. dag_id=postgres_dag, task_id=insert_values, execution_date=20230614T135646, start_date=20230614T135652, end_date=20230614T135653
[2023-06-14T13:56:53.699+0000] {standard_task_runner.py:109} ERROR - Failed to execute job 20 for task insert_values (relation "mytime" does not exist
LINE 2: INSERT INTO myTime VALUES (CURRENT_TIMESTAMP);
                    ^
; 108)
[2023-06-14T13:56:53.732+0000] {local_task_job_runner.py:225} INFO - Task exited with return code 1
[2023-06-14T13:56:53.769+0000] {taskinstance.py:2651} INFO - 0 downstream tasks scheduled from follow-on schedule check
