[2023-06-14T13:45:10.509+0000] {taskinstance.py:1103} INFO - Dependencies all met for dep_context=non-requeueable deps ti=<TaskInstance: postgres_dag.insert_values scheduled__2023-04-22T00:00:00+00:00 [queued]>
[2023-06-14T13:45:10.526+0000] {taskinstance.py:1103} INFO - Dependencies all met for dep_context=requeueable deps ti=<TaskInstance: postgres_dag.insert_values scheduled__2023-04-22T00:00:00+00:00 [queued]>
[2023-06-14T13:45:10.527+0000] {taskinstance.py:1308} INFO - Starting attempt 1 of 2
[2023-06-14T13:45:10.594+0000] {taskinstance.py:1327} INFO - Executing <Task(PostgresOperator): insert_values> on 2023-04-22 00:00:00+00:00
[2023-06-14T13:45:10.635+0000] {standard_task_runner.py:57} INFO - Started process 287 to run task
[2023-06-14T13:45:10.643+0000] {standard_task_runner.py:84} INFO - Running: ['***', 'tasks', 'run', 'postgres_dag', 'insert_values', 'scheduled__2023-04-22T00:00:00+00:00', '--job-id', '39', '--raw', '--subdir', 'DAGS_FOLDER/create_database_postgres.py', '--cfg-path', '/tmp/tmpti41nkqx']
[2023-06-14T13:45:10.650+0000] {standard_task_runner.py:85} INFO - Job 39: Subtask insert_values
[2023-06-14T13:45:10.944+0000] {task_command.py:410} INFO - Running <TaskInstance: postgres_dag.insert_values scheduled__2023-04-22T00:00:00+00:00 [running]> on host 770b1916921e
[2023-06-14T13:45:11.303+0000] {taskinstance.py:1547} INFO - Exporting env vars: AIRFLOW_CTX_DAG_OWNER='***' AIRFLOW_CTX_DAG_ID='postgres_dag' AIRFLOW_CTX_TASK_ID='insert_values' AIRFLOW_CTX_EXECUTION_DATE='2023-04-22T00:00:00+00:00' AIRFLOW_CTX_TRY_NUMBER='1' AIRFLOW_CTX_DAG_RUN_ID='scheduled__2023-04-22T00:00:00+00:00'
[2023-06-14T13:45:11.309+0000] {sql.py:262} INFO - Executing: 
INSERT INTO myTime VALUES (CURRENT_TIMESTAMP);
[2023-06-14T13:45:11.393+0000] {taskinstance.py:1824} ERROR - Task failed with exception
Traceback (most recent call last):
  File "/home/airflow/.local/lib/python3.7/site-packages/airflow/providers/common/sql/operators/sql.py", line 263, in execute
    hook = self.get_db_hook()
  File "/home/airflow/.local/lib/python3.7/site-packages/airflow/providers/common/sql/operators/sql.py", line 181, in get_db_hook
    return self._hook
  File "/home/airflow/.local/lib/python3.7/site-packages/cached_property.py", line 36, in __get__
    value = obj.__dict__[self.func.__name__] = self.func(obj)
  File "/home/airflow/.local/lib/python3.7/site-packages/airflow/providers/common/sql/operators/sql.py", line 143, in _hook
    conn = BaseHook.get_connection(self.conn_id)
  File "/home/airflow/.local/lib/python3.7/site-packages/airflow/hooks/base.py", line 72, in get_connection
    conn = Connection.get_connection_from_secrets(conn_id)
  File "/home/airflow/.local/lib/python3.7/site-packages/airflow/models/connection.py", line 434, in get_connection_from_secrets
    raise AirflowNotFoundException(f"The conn_id `{conn_id}` isn't defined")
airflow.exceptions.AirflowNotFoundException: The conn_id `postgres_conn` isn't defined
[2023-06-14T13:45:11.405+0000] {taskinstance.py:1350} INFO - Marking task as UP_FOR_RETRY. dag_id=postgres_dag, task_id=insert_values, execution_date=20230422T000000, start_date=20230614T134510, end_date=20230614T134511
[2023-06-14T13:45:11.480+0000] {standard_task_runner.py:109} ERROR - Failed to execute job 39 for task insert_values (The conn_id `postgres_conn` isn't defined; 287)
[2023-06-14T13:45:11.585+0000] {local_task_job_runner.py:225} INFO - Task exited with return code 1
[2023-06-14T13:45:11.622+0000] {taskinstance.py:2651} INFO - 0 downstream tasks scheduled from follow-on schedule check
[2023-06-14T13:54:05.714+0000] {taskinstance.py:1103} INFO - Dependencies all met for dep_context=non-requeueable deps ti=<TaskInstance: postgres_dag.insert_values scheduled__2023-04-22T00:00:00+00:00 [queued]>
[2023-06-14T13:54:05.747+0000] {taskinstance.py:1103} INFO - Dependencies all met for dep_context=requeueable deps ti=<TaskInstance: postgres_dag.insert_values scheduled__2023-04-22T00:00:00+00:00 [queued]>
[2023-06-14T13:54:05.748+0000] {taskinstance.py:1308} INFO - Starting attempt 1 of 2
[2023-06-14T13:54:05.785+0000] {taskinstance.py:1327} INFO - Executing <Task(PostgresOperator): insert_values> on 2023-04-22 00:00:00+00:00
[2023-06-14T13:54:05.799+0000] {standard_task_runner.py:57} INFO - Started process 107 to run task
[2023-06-14T13:54:05.832+0000] {standard_task_runner.py:84} INFO - Running: ['***', 'tasks', 'run', 'postgres_dag', 'insert_values', 'scheduled__2023-04-22T00:00:00+00:00', '--job-id', '17', '--raw', '--subdir', 'DAGS_FOLDER/create_database_postgres.py', '--cfg-path', '/tmp/tmpi4qyql9a']
[2023-06-14T13:54:05.836+0000] {standard_task_runner.py:85} INFO - Job 17: Subtask insert_values
[2023-06-14T13:54:06.101+0000] {task_command.py:410} INFO - Running <TaskInstance: postgres_dag.insert_values scheduled__2023-04-22T00:00:00+00:00 [running]> on host e981f43aaef1
[2023-06-14T13:54:06.336+0000] {taskinstance.py:1547} INFO - Exporting env vars: AIRFLOW_CTX_DAG_OWNER='***' AIRFLOW_CTX_DAG_ID='postgres_dag' AIRFLOW_CTX_TASK_ID='insert_values' AIRFLOW_CTX_EXECUTION_DATE='2023-04-22T00:00:00+00:00' AIRFLOW_CTX_TRY_NUMBER='1' AIRFLOW_CTX_DAG_RUN_ID='scheduled__2023-04-22T00:00:00+00:00'
[2023-06-14T13:54:06.338+0000] {sql.py:262} INFO - Executing: 
INSERT INTO myTime VALUES (CURRENT_TIMESTAMP);
[2023-06-14T13:54:06.374+0000] {taskinstance.py:1824} ERROR - Task failed with exception
Traceback (most recent call last):
  File "/home/airflow/.local/lib/python3.7/site-packages/airflow/providers/common/sql/operators/sql.py", line 263, in execute
    hook = self.get_db_hook()
  File "/home/airflow/.local/lib/python3.7/site-packages/airflow/providers/common/sql/operators/sql.py", line 181, in get_db_hook
    return self._hook
  File "/home/airflow/.local/lib/python3.7/site-packages/cached_property.py", line 36, in __get__
    value = obj.__dict__[self.func.__name__] = self.func(obj)
  File "/home/airflow/.local/lib/python3.7/site-packages/airflow/providers/common/sql/operators/sql.py", line 143, in _hook
    conn = BaseHook.get_connection(self.conn_id)
  File "/home/airflow/.local/lib/python3.7/site-packages/airflow/hooks/base.py", line 72, in get_connection
    conn = Connection.get_connection_from_secrets(conn_id)
  File "/home/airflow/.local/lib/python3.7/site-packages/airflow/models/connection.py", line 434, in get_connection_from_secrets
    raise AirflowNotFoundException(f"The conn_id `{conn_id}` isn't defined")
airflow.exceptions.AirflowNotFoundException: The conn_id `postgres_conn` isn't defined
[2023-06-14T13:54:06.380+0000] {taskinstance.py:1350} INFO - Marking task as UP_FOR_RETRY. dag_id=postgres_dag, task_id=insert_values, execution_date=20230422T000000, start_date=20230614T135405, end_date=20230614T135406
[2023-06-14T13:54:06.399+0000] {standard_task_runner.py:109} ERROR - Failed to execute job 17 for task insert_values (The conn_id `postgres_conn` isn't defined; 107)
[2023-06-14T13:54:06.465+0000] {local_task_job_runner.py:225} INFO - Task exited with return code 1
[2023-06-14T13:54:06.506+0000] {taskinstance.py:2651} INFO - 0 downstream tasks scheduled from follow-on schedule check
[2023-06-14T13:56:53.419+0000] {taskinstance.py:1103} INFO - Dependencies all met for dep_context=non-requeueable deps ti=<TaskInstance: postgres_dag.insert_values scheduled__2023-04-22T00:00:00+00:00 [queued]>
[2023-06-14T13:56:53.445+0000] {taskinstance.py:1103} INFO - Dependencies all met for dep_context=requeueable deps ti=<TaskInstance: postgres_dag.insert_values scheduled__2023-04-22T00:00:00+00:00 [queued]>
[2023-06-14T13:56:53.446+0000] {taskinstance.py:1308} INFO - Starting attempt 1 of 2
[2023-06-14T13:56:53.467+0000] {taskinstance.py:1327} INFO - Executing <Task(PostgresOperator): insert_values> on 2023-04-22 00:00:00+00:00
[2023-06-14T13:56:53.479+0000] {standard_task_runner.py:57} INFO - Started process 110 to run task
[2023-06-14T13:56:53.490+0000] {standard_task_runner.py:84} INFO - Running: ['***', 'tasks', 'run', 'postgres_dag', 'insert_values', 'scheduled__2023-04-22T00:00:00+00:00', '--job-id', '22', '--raw', '--subdir', 'DAGS_FOLDER/create_database_postgres.py', '--cfg-path', '/tmp/tmpqq67ntmb']
[2023-06-14T13:56:53.491+0000] {standard_task_runner.py:85} INFO - Job 22: Subtask insert_values
[2023-06-14T13:56:53.607+0000] {task_command.py:410} INFO - Running <TaskInstance: postgres_dag.insert_values scheduled__2023-04-22T00:00:00+00:00 [running]> on host 366197f8877d
[2023-06-14T13:56:53.802+0000] {taskinstance.py:1547} INFO - Exporting env vars: AIRFLOW_CTX_DAG_OWNER='***' AIRFLOW_CTX_DAG_ID='postgres_dag' AIRFLOW_CTX_TASK_ID='insert_values' AIRFLOW_CTX_EXECUTION_DATE='2023-04-22T00:00:00+00:00' AIRFLOW_CTX_TRY_NUMBER='1' AIRFLOW_CTX_DAG_RUN_ID='scheduled__2023-04-22T00:00:00+00:00'
[2023-06-14T13:56:53.803+0000] {sql.py:262} INFO - Executing: 
INSERT INTO myTime VALUES (CURRENT_TIMESTAMP);
[2023-06-14T13:56:53.826+0000] {base.py:73} INFO - Using connection ID 'postgres_connection' for task execution.
[2023-06-14T13:56:53.890+0000] {base.py:73} INFO - Using connection ID 'postgres_connection' for task execution.
[2023-06-14T13:56:53.919+0000] {sql.py:375} INFO - Running statement: 
INSERT INTO myTime VALUES (CURRENT_TIMESTAMP);, parameters: None
[2023-06-14T13:56:53.922+0000] {taskinstance.py:1824} ERROR - Task failed with exception
Traceback (most recent call last):
  File "/home/airflow/.local/lib/python3.7/site-packages/airflow/providers/common/sql/operators/sql.py", line 274, in execute
    **extra_kwargs,
  File "/home/airflow/.local/lib/python3.7/site-packages/airflow/providers/common/sql/hooks/sql.py", line 349, in run
    self._run_command(cur, sql_statement, parameters)
  File "/home/airflow/.local/lib/python3.7/site-packages/airflow/providers/common/sql/hooks/sql.py", line 380, in _run_command
    cur.execute(sql_statement)
psycopg2.errors.UndefinedTable: relation "mytime" does not exist
LINE 2: INSERT INTO myTime VALUES (CURRENT_TIMESTAMP);
                    ^

[2023-06-14T13:56:53.940+0000] {taskinstance.py:1350} INFO - Marking task as UP_FOR_RETRY. dag_id=postgres_dag, task_id=insert_values, execution_date=20230422T000000, start_date=20230614T135653, end_date=20230614T135653
[2023-06-14T13:56:53.957+0000] {standard_task_runner.py:109} ERROR - Failed to execute job 22 for task insert_values (relation "mytime" does not exist
LINE 2: INSERT INTO myTime VALUES (CURRENT_TIMESTAMP);
                    ^
; 110)
[2023-06-14T13:56:54.038+0000] {local_task_job_runner.py:225} INFO - Task exited with return code 1
[2023-06-14T13:56:54.063+0000] {taskinstance.py:2651} INFO - 0 downstream tasks scheduled from follow-on schedule check
