[2023-06-14T13:39:54.079+0000] {taskinstance.py:1103} INFO - Dependencies all met for dep_context=non-requeueable deps ti=<TaskInstance: postgres_dag.create_table scheduled__2023-04-20T00:00:00+00:00 [queued]>
[2023-06-14T13:39:54.133+0000] {taskinstance.py:1103} INFO - Dependencies all met for dep_context=requeueable deps ti=<TaskInstance: postgres_dag.create_table scheduled__2023-04-20T00:00:00+00:00 [queued]>
[2023-06-14T13:39:54.135+0000] {taskinstance.py:1308} INFO - Starting attempt 1 of 2
[2023-06-14T13:39:54.175+0000] {taskinstance.py:1327} INFO - Executing <Task(PostgresOperator): create_table> on 2023-04-20 00:00:00+00:00
[2023-06-14T13:39:54.209+0000] {standard_task_runner.py:57} INFO - Started process 119 to run task
[2023-06-14T13:39:54.219+0000] {standard_task_runner.py:84} INFO - Running: ['***', 'tasks', 'run', 'postgres_dag', 'create_table', 'scheduled__2023-04-20T00:00:00+00:00', '--job-id', '4', '--raw', '--subdir', 'DAGS_FOLDER/create_database_postgres.py', '--cfg-path', '/tmp/tmp7z475g3b']
[2023-06-14T13:39:54.226+0000] {standard_task_runner.py:85} INFO - Job 4: Subtask create_table
[2023-06-14T13:39:54.461+0000] {task_command.py:410} INFO - Running <TaskInstance: postgres_dag.create_table scheduled__2023-04-20T00:00:00+00:00 [running]> on host 770b1916921e
[2023-06-14T13:39:54.994+0000] {taskinstance.py:1547} INFO - Exporting env vars: AIRFLOW_CTX_DAG_OWNER='***' AIRFLOW_CTX_DAG_ID='postgres_dag' AIRFLOW_CTX_TASK_ID='create_table' AIRFLOW_CTX_EXECUTION_DATE='2023-04-20T00:00:00+00:00' AIRFLOW_CTX_TRY_NUMBER='1' AIRFLOW_CTX_DAG_RUN_ID='scheduled__2023-04-20T00:00:00+00:00'
[2023-06-14T13:39:54.997+0000] {sql.py:262} INFO - Executing: 
    CREATE TABLE IF NOT EXISTS sample_table (
    name VARCHAR(50),
    age INTEGER,
    email VARCHAR(100)
);
[2023-06-14T13:39:55.112+0000] {taskinstance.py:1824} ERROR - Task failed with exception
Traceback (most recent call last):
  File "/home/airflow/.local/lib/python3.7/site-packages/airflow/providers/common/sql/operators/sql.py", line 263, in execute
    hook = self.get_db_hook()
  File "/home/airflow/.local/lib/python3.7/site-packages/airflow/providers/common/sql/operators/sql.py", line 181, in get_db_hook
    return self._hook
  File "/home/airflow/.local/lib/python3.7/site-packages/cached_property.py", line 36, in __get__
    value = obj.__dict__[self.func.__name__] = self.func(obj)
  File "/home/airflow/.local/lib/python3.7/site-packages/airflow/providers/common/sql/operators/sql.py", line 143, in _hook
    conn = BaseHook.get_connection(self.conn_id)
  File "/home/airflow/.local/lib/python3.7/site-packages/airflow/hooks/base.py", line 72, in get_connection
    conn = Connection.get_connection_from_secrets(conn_id)
  File "/home/airflow/.local/lib/python3.7/site-packages/airflow/models/connection.py", line 434, in get_connection_from_secrets
    raise AirflowNotFoundException(f"The conn_id `{conn_id}` isn't defined")
airflow.exceptions.AirflowNotFoundException: The conn_id `postgres_conn` isn't defined
[2023-06-14T13:39:55.159+0000] {taskinstance.py:1350} INFO - Marking task as UP_FOR_RETRY. dag_id=postgres_dag, task_id=create_table, execution_date=20230420T000000, start_date=20230614T133954, end_date=20230614T133955
[2023-06-14T13:39:55.329+0000] {standard_task_runner.py:109} ERROR - Failed to execute job 4 for task create_table (The conn_id `postgres_conn` isn't defined; 119)
[2023-06-14T13:39:55.469+0000] {local_task_job_runner.py:225} INFO - Task exited with return code 1
[2023-06-14T13:39:56.416+0000] {taskinstance.py:2651} INFO - 0 downstream tasks scheduled from follow-on schedule check
[2023-06-14T13:48:47.020+0000] {taskinstance.py:1103} INFO - Dependencies all met for dep_context=non-requeueable deps ti=<TaskInstance: postgres_dag.create_table scheduled__2023-04-20T00:00:00+00:00 [queued]>
[2023-06-14T13:48:47.048+0000] {taskinstance.py:1103} INFO - Dependencies all met for dep_context=requeueable deps ti=<TaskInstance: postgres_dag.create_table scheduled__2023-04-20T00:00:00+00:00 [queued]>
[2023-06-14T13:48:47.053+0000] {taskinstance.py:1308} INFO - Starting attempt 1 of 2
[2023-06-14T13:48:47.123+0000] {taskinstance.py:1327} INFO - Executing <Task(PostgresOperator): create_table> on 2023-04-20 00:00:00+00:00
[2023-06-14T13:48:47.135+0000] {standard_task_runner.py:57} INFO - Started process 74 to run task
[2023-06-14T13:48:47.179+0000] {standard_task_runner.py:84} INFO - Running: ['***', 'tasks', 'run', 'postgres_dag', 'create_table', 'scheduled__2023-04-20T00:00:00+00:00', '--job-id', '3', '--raw', '--subdir', 'DAGS_FOLDER/create_database_postgres.py', '--cfg-path', '/tmp/tmp3t93g39l']
[2023-06-14T13:48:47.183+0000] {standard_task_runner.py:85} INFO - Job 3: Subtask create_table
[2023-06-14T13:48:47.479+0000] {task_command.py:410} INFO - Running <TaskInstance: postgres_dag.create_table scheduled__2023-04-20T00:00:00+00:00 [running]> on host 25d93391a9f5
[2023-06-14T13:48:47.858+0000] {taskinstance.py:1547} INFO - Exporting env vars: AIRFLOW_CTX_DAG_OWNER='***' AIRFLOW_CTX_DAG_ID='postgres_dag' AIRFLOW_CTX_TASK_ID='create_table' AIRFLOW_CTX_EXECUTION_DATE='2023-04-20T00:00:00+00:00' AIRFLOW_CTX_TRY_NUMBER='1' AIRFLOW_CTX_DAG_RUN_ID='scheduled__2023-04-20T00:00:00+00:00'
[2023-06-14T13:48:47.859+0000] {sql.py:262} INFO - Executing: 
    CREATE TABLE IF NOT EXISTS sample_table (
    name VARCHAR(50),
    age INTEGER,
    email VARCHAR(100)
);
[2023-06-14T13:48:47.914+0000] {taskinstance.py:1824} ERROR - Task failed with exception
Traceback (most recent call last):
  File "/home/airflow/.local/lib/python3.7/site-packages/airflow/providers/common/sql/operators/sql.py", line 263, in execute
    hook = self.get_db_hook()
  File "/home/airflow/.local/lib/python3.7/site-packages/airflow/providers/common/sql/operators/sql.py", line 181, in get_db_hook
    return self._hook
  File "/home/airflow/.local/lib/python3.7/site-packages/cached_property.py", line 36, in __get__
    value = obj.__dict__[self.func.__name__] = self.func(obj)
  File "/home/airflow/.local/lib/python3.7/site-packages/airflow/providers/common/sql/operators/sql.py", line 143, in _hook
    conn = BaseHook.get_connection(self.conn_id)
  File "/home/airflow/.local/lib/python3.7/site-packages/airflow/hooks/base.py", line 72, in get_connection
    conn = Connection.get_connection_from_secrets(conn_id)
  File "/home/airflow/.local/lib/python3.7/site-packages/airflow/models/connection.py", line 434, in get_connection_from_secrets
    raise AirflowNotFoundException(f"The conn_id `{conn_id}` isn't defined")
airflow.exceptions.AirflowNotFoundException: The conn_id `postgres_connection` isn't defined
[2023-06-14T13:48:47.919+0000] {taskinstance.py:1350} INFO - Marking task as UP_FOR_RETRY. dag_id=postgres_dag, task_id=create_table, execution_date=20230420T000000, start_date=20230614T134847, end_date=20230614T134847
[2023-06-14T13:48:47.958+0000] {standard_task_runner.py:109} ERROR - Failed to execute job 3 for task create_table (The conn_id `postgres_connection` isn't defined; 74)
[2023-06-14T13:48:47.989+0000] {local_task_job_runner.py:225} INFO - Task exited with return code 1
[2023-06-14T13:48:48.037+0000] {taskinstance.py:2651} INFO - 0 downstream tasks scheduled from follow-on schedule check
[2023-06-14T13:54:02.008+0000] {taskinstance.py:1103} INFO - Dependencies all met for dep_context=non-requeueable deps ti=<TaskInstance: postgres_dag.create_table scheduled__2023-04-20T00:00:00+00:00 [queued]>
[2023-06-14T13:54:02.037+0000] {taskinstance.py:1103} INFO - Dependencies all met for dep_context=requeueable deps ti=<TaskInstance: postgres_dag.create_table scheduled__2023-04-20T00:00:00+00:00 [queued]>
[2023-06-14T13:54:02.038+0000] {taskinstance.py:1308} INFO - Starting attempt 1 of 2
[2023-06-14T13:54:02.086+0000] {taskinstance.py:1327} INFO - Executing <Task(PostgresOperator): create_table> on 2023-04-20 00:00:00+00:00
[2023-06-14T13:54:02.092+0000] {standard_task_runner.py:57} INFO - Started process 76 to run task
[2023-06-14T13:54:02.102+0000] {standard_task_runner.py:84} INFO - Running: ['***', 'tasks', 'run', 'postgres_dag', 'create_table', 'scheduled__2023-04-20T00:00:00+00:00', '--job-id', '4', '--raw', '--subdir', 'DAGS_FOLDER/create_database_postgres.py', '--cfg-path', '/tmp/tmpyy7cb1ca']
[2023-06-14T13:54:02.104+0000] {standard_task_runner.py:85} INFO - Job 4: Subtask create_table
[2023-06-14T13:54:02.331+0000] {task_command.py:410} INFO - Running <TaskInstance: postgres_dag.create_table scheduled__2023-04-20T00:00:00+00:00 [running]> on host e981f43aaef1
[2023-06-14T13:54:02.654+0000] {taskinstance.py:1547} INFO - Exporting env vars: AIRFLOW_CTX_DAG_OWNER='***' AIRFLOW_CTX_DAG_ID='postgres_dag' AIRFLOW_CTX_TASK_ID='create_table' AIRFLOW_CTX_EXECUTION_DATE='2023-04-20T00:00:00+00:00' AIRFLOW_CTX_TRY_NUMBER='1' AIRFLOW_CTX_DAG_RUN_ID='scheduled__2023-04-20T00:00:00+00:00'
[2023-06-14T13:54:02.659+0000] {sql.py:262} INFO - Executing: 
    CREATE TABLE IF NOT EXISTS sample_table (
    name VARCHAR(50),
    age INTEGER,
    email VARCHAR(100)
);
[2023-06-14T13:54:02.704+0000] {base.py:73} INFO - Using connection ID 'postgres_connection' for task execution.
[2023-06-14T13:54:03.044+0000] {base.py:73} INFO - Using connection ID 'postgres_connection' for task execution.
[2023-06-14T13:54:03.079+0000] {sql.py:375} INFO - Running statement: 
    CREATE TABLE IF NOT EXISTS sample_table (
    name VARCHAR(50),
    age INTEGER,
    email VARCHAR(100)
);, parameters: None
[2023-06-14T13:54:03.191+0000] {taskinstance.py:1350} INFO - Marking task as SUCCESS. dag_id=postgres_dag, task_id=create_table, execution_date=20230420T000000, start_date=20230614T135402, end_date=20230614T135403
[2023-06-14T13:54:03.348+0000] {local_task_job_runner.py:225} INFO - Task exited with return code 0
[2023-06-14T13:54:03.375+0000] {taskinstance.py:2651} INFO - 1 downstream tasks scheduled from follow-on schedule check
[2023-06-14T13:56:47.766+0000] {taskinstance.py:1103} INFO - Dependencies all met for dep_context=non-requeueable deps ti=<TaskInstance: postgres_dag.create_table scheduled__2023-04-20T00:00:00+00:00 [queued]>
[2023-06-14T13:56:47.829+0000] {taskinstance.py:1103} INFO - Dependencies all met for dep_context=requeueable deps ti=<TaskInstance: postgres_dag.create_table scheduled__2023-04-20T00:00:00+00:00 [queued]>
[2023-06-14T13:56:47.834+0000] {taskinstance.py:1308} INFO - Starting attempt 1 of 2
[2023-06-14T13:56:47.926+0000] {taskinstance.py:1327} INFO - Executing <Task(PostgresOperator): create_table> on 2023-04-20 00:00:00+00:00
[2023-06-14T13:56:47.972+0000] {standard_task_runner.py:57} INFO - Started process 74 to run task
[2023-06-14T13:56:48.010+0000] {standard_task_runner.py:84} INFO - Running: ['***', 'tasks', 'run', 'postgres_dag', 'create_table', 'scheduled__2023-04-20T00:00:00+00:00', '--job-id', '4', '--raw', '--subdir', 'DAGS_FOLDER/create_database_postgres.py', '--cfg-path', '/tmp/tmp8k3txr0x']
[2023-06-14T13:56:48.039+0000] {standard_task_runner.py:85} INFO - Job 4: Subtask create_table
[2023-06-14T13:56:48.492+0000] {task_command.py:410} INFO - Running <TaskInstance: postgres_dag.create_table scheduled__2023-04-20T00:00:00+00:00 [running]> on host 366197f8877d
[2023-06-14T13:56:49.319+0000] {taskinstance.py:1547} INFO - Exporting env vars: AIRFLOW_CTX_DAG_OWNER='***' AIRFLOW_CTX_DAG_ID='postgres_dag' AIRFLOW_CTX_TASK_ID='create_table' AIRFLOW_CTX_EXECUTION_DATE='2023-04-20T00:00:00+00:00' AIRFLOW_CTX_TRY_NUMBER='1' AIRFLOW_CTX_DAG_RUN_ID='scheduled__2023-04-20T00:00:00+00:00'
[2023-06-14T13:56:49.329+0000] {sql.py:262} INFO - Executing: 
    CREATE TABLE IF NOT EXISTS sample_table (
    name VARCHAR(50),
    age INTEGER,
    email VARCHAR(100)
);
[2023-06-14T13:56:49.415+0000] {base.py:73} INFO - Using connection ID 'postgres_connection' for task execution.
[2023-06-14T13:56:49.762+0000] {base.py:73} INFO - Using connection ID 'postgres_connection' for task execution.
[2023-06-14T13:56:49.781+0000] {sql.py:375} INFO - Running statement: 
    CREATE TABLE IF NOT EXISTS sample_table (
    name VARCHAR(50),
    age INTEGER,
    email VARCHAR(100)
);, parameters: None
[2023-06-14T13:56:49.802+0000] {taskinstance.py:1824} ERROR - Task failed with exception
Traceback (most recent call last):
  File "/home/airflow/.local/lib/python3.7/site-packages/airflow/providers/common/sql/operators/sql.py", line 274, in execute
    **extra_kwargs,
  File "/home/airflow/.local/lib/python3.7/site-packages/airflow/providers/common/sql/hooks/sql.py", line 349, in run
    self._run_command(cur, sql_statement, parameters)
  File "/home/airflow/.local/lib/python3.7/site-packages/airflow/providers/common/sql/hooks/sql.py", line 380, in _run_command
    cur.execute(sql_statement)
psycopg2.errors.UniqueViolation: duplicate key value violates unique constraint "pg_type_typname_nsp_index"
DETAIL:  Key (typname, typnamespace)=(sample_table, 2200) already exists.

[2023-06-14T13:56:49.873+0000] {taskinstance.py:1350} INFO - Marking task as UP_FOR_RETRY. dag_id=postgres_dag, task_id=create_table, execution_date=20230420T000000, start_date=20230614T135647, end_date=20230614T135649
[2023-06-14T13:56:49.893+0000] {standard_task_runner.py:109} ERROR - Failed to execute job 4 for task create_table (duplicate key value violates unique constraint "pg_type_typname_nsp_index"
DETAIL:  Key (typname, typnamespace)=(sample_table, 2200) already exists.
; 74)
[2023-06-14T13:56:50.016+0000] {local_task_job_runner.py:225} INFO - Task exited with return code 1
[2023-06-14T13:56:50.151+0000] {taskinstance.py:2651} INFO - 0 downstream tasks scheduled from follow-on schedule check
